---
template : "post"
title : "47. 예외 처리"
category : ""
tags : "DeepDive"
created: "2024-01-12"
---

# 47. 예외 처리


발생한 에러에 대해 대처하지 않고 방치하면 프로그램은 강제 종료된다.


try…catch 문을 사용해 발생한 에러에 대응하면 프로그램이 강제 종료되지 않는다.


## try…catch…finally 문

- 에러 처리 코드를 미리 등록해 두고 에러가 발생하면 에러 처리코드로 점프하는 방법이다.
- try…catch…finally 문으로 3개의 코드 블록으로 구성된다.
- catch 문은 생략이 가능하지만 생략한다면 try문은 의미가 없어진다.
- finally 문이 불필요하다면 생략이 가능하다.
- try 코드 블록에 포함된 문 중에서 에러가 발생하면 발생한 에러는 catch 문의 인수전달되고,
- catch 코드 블록이 실행된다.
- finally 코드 블록은 에러 발생과 상관없이 반드시 한 번 실행된다.

## Error 객체

- Error 생성자 함수는 에러 객체를 생성한다.
- Error 생성자 함수에는 에러를 상세히 설명하는 에러 메시지를 인수로 전달할 수 있다.
- Error 생성자 함수가 생성한 에러는 message 프로퍼티와 stack 프로퍼티를 갖는다.
- message  프로퍼티의 값은 인수로 전달받은 에러 메시지다.
- stack 프로퍼티의 값은 에러를 발생시킨 콜스택의 호출 정보를 문자열로 나타낸다.

```javascript
const error = new Error('invalid');
```

- 7가지의 에러 객체를 생성할 수 있는 생성자 함수를 제공한다.
- 모든 에러 객체의 프로토타입은 모두 Error.prototype을 상속한다.

| 생성자 함수         | 인스턴스                                                  |
| -------------- | ----------------------------------------------------- |
| Error          | 일반적인 에러 객체                                            |
| SyntaxError    | 자바스크립트 문법에 맞지 않는 문을 해석할 대 발생하는 에러 객체                  |
| ReferenceError | 참조할 수 없는 식별자를 참조했을 때 발생하는 에러 객체                       |
| TypeError      | 피연산자 도는 인수의 데이터 타입이 유효하지 않을 때 발생하는 에러 객체              |
| RangeError     | 숫자값의 허용 범위를 벗어났을 때 발생하는 에러 객체                         |
| URIError       | encodeURL 또는 decodeURI 함수에 부적절한 인수를 전달했을 때 발생하는 에러 객체 |
| EvalError      | eval 함수에서 발생하는 에러 객체                                  |


## throw 문

- 에러를 발생시키려면 try 코드 블록에서 throw 문으로 에러 객체를 던져야 한다.
- throw 문의 표현식은 어떤 값이라도 상관 없다.
- 일반적으로는 에러 객체를 지정한다.
- 에러를 던지면 catch 문의 에러 변수가 생성되고 던져진 에러 객체가 할당되고 코드 블록이 실행된다.

```javascript
try {
	throw new Error('somting wrong');
} catch (error) {
	console.log(error);
}
```


## 에러의 전파

- 에러는 호출자 방향으로 전파된다.
- 즉,  콜 스택의 아래방향(실행 중인 실행 컨텍스트가 푸시되기 직전에 푸쉬된 실행 컨텍스트 방향)으로 전파된다.
- throw된 에러를 캐치하지 않으면 호출자 방향으로 전파된다.
- throw된 에러를 어디서도 캐치하지 않으면 프로그램은 강제 종료된다.

```javascript
try {
	setTimeout(() => { throw new Error('Error!') }, 1000);
} catch (e) {
	// 에어를 캐치하지 못한다.
	console.error('캐치한 에러', e);
}
```

- 비동기 함수나 프로미스 후속 처리 메서드의 콜백 함수는 호출자가 없다.
- 태스크 큐나 마이클태스크 큐에 일시 저장되었다가 콜 스택이 비면 이벤트 루프에 의해 콜 스택으로 푸시되어 실행된다.
- 이때 콜 스택에 푸쉬된 콜백 함수는 콜 스택의 가장 하부에 존재하게된다.
- 따라서 에러를 전파할 호출자가 존재하지 않기 때문이다.
